Workbook

Sheet Data
A1: title | B1: magnitude | C1: date_time | D1: cdi | E1: mmi | F1: alert | G1: tsunami | H1: sig | I1: net | J1: nst | K1: dmin | L1: gap | M1: magType | N1: depth | O1: latitude | P1: longitude | Q1: location | R1: continent | S1: country | T1: DateTime_Converted | U1: Title_Pattern | V1: magType_Normalized | W1: Duplicate_Flag | X1: Year | Y1: Magnitude_Band | Z1: Alert_Audit
A2: M 6.5 - 42 km W of Sola, Vanuatu | B2: 6.5 | C2: 16/08/2023 12:47 | D2: 7 | E2: 4 | F2: green | G2: 0 | H2: 657 | I2: us | J2: 114 | K2: 7.177 | L2: 25 | M2: mww | N2: 192.955 | O2: -13.8814 | P2: 167.158 | Q2: Sola, Vanuatu | S2: Vanuatu | T2: =DATE(MID(C2,7,4),MID(C2,4,2),MID(C2,1,2))+TIME(MID(C2,12,2),MID(C2,15,2),0) | U2: =IF(ISNUMBER(VALUE(MID(A2,7,1))),"Distance-prefix pattern","Named-region pattern") | V2: =LOWER(M2) | W2: =IF(COUNTIFS($A$2:$A$1001,A2,$C$2:$C$1001,C2)>1,"Duplicate","Unique") | X2: =YEAR(T2) | Y2: =IF(B2<6.5,"<6.5",IF(B2<7,"6.5–6.9",IF(B2<7.5,"7.0–7.4",IF(B2<8,"7.5–7.9","8.0+")))) | Z2: =IF(F2="","Blank",F2)
A3: M 6.5 - 43 km S of Intipucá, El Salvador | B3: 6.5 | C3: 19/07/2023 00:22 | D3: 8 | E3: 6 | F3: yellow | G3: 0 | H3: 775 | I3: us | J3: 92 | K3: 0.679 | L3: 40 | M3: mww | N3: 69.727 | O3: 12.814 | P3: -88.1265 | Q3: Intipucá, El Salvador | T3: =DATE(MID(C3,7,4),MID(C3,4,2),MID(C3,1,2))+TIME(MID(C3,12,2),MID(C3,15,2),0) | U3: =IF(ISNUMBER(VALUE(MID(A3,7,1))),"Distance-prefix pattern","Named-region pattern") | V3: =LOWER(M3) | W3: =IF(COUNTIFS($A$2:$A$1001,A3,$C$2:$C$1001,C3)>1,"Duplicate","Unique") | X3: =YEAR(T3) | Y3: =IF(B3<6.5,"<6.5",IF(B3<7,"6.5–6.9",IF(B3<7.5,"7.0–7.4",IF(B3<8,"7.5–7.9","8.0+")))) | Z3: =IF(F3="","Blank",F3)
A4: M 6.6 - 25 km ESE of Loncopué, Argentina | B4: 6.6 | C4: 17/07/2023 03:05 | D4: 7 | E4: 5 | F4: green | G4: 0 | H4: 899 | I4: us | J4: 70 | K4: 1.634 | L4: 28 | M4: mww | N4: 171.371 | O4: -38.1911 | P4: -70.3731 | Q4: Loncopué, Argentina | R4: South America | S4: Argentina | T4: =DATE(MID(C4,7,4),MID(C4,4,2),MID(C4,1,2))+TIME(MID(C4,12,2),MID(C4,15,2),0) | U4: =IF(ISNUMBER(VALUE(MID(A4,7,1))),"Distance-prefix pattern","Named-region pattern") | V4: =LOWER(M4) | W4: =IF(COUNTIFS($A$2:$A$1001,A4,$C$2:$C$1001,C4)>1,"Duplicate","Unique") | X4: =YEAR(T4) | Y4: =IF(B4<6.5,"<6.5",IF(B4<7,"6.5–6.9",IF(B4<7.5,"7.0–7.4",IF(B4<8,"7.5–7.9","8.0+")))) | Z4: =IF(F4="","Blank",F4)
A5: M 7.2 - 98 km S of Sand Point, Alaska | B5: 7.2 | C5: 16/07/2023 06:48 | D5: 6 | E5: 6 | F5: green | G5: 1 | H5: 860 | I5: us | J5: 173 | K5: 0.907 | L5: 36 | M5: mww | N5: 32.571 | O5: 54.3844 | P5: -160.699 | Q5: Sand Point, Alaska | T5: =DATE(MID(C5,7,4),MID(C5,4,2),MID(C5,1,2))+TIME(MID(C5,12,2),MID(C5,15,2),0) | U5: =IF(ISNUMBER(VALUE(MID(A5,7,1))),"Distance-prefix pattern","Named-region pattern") | V5: =LOWER(M5) | W5: =IF(COUNTIFS($A$2:$A$1001,A5,$C$2:$C$1001,C5)>1,"Duplicate","Unique") | X5: =YEAR(T5) | Y5: =IF(B5<6.5,"<6.5",IF(B5<7,"6.5–6.9",IF(B5<7.5,"7.0–7.4",IF(B5<8,"7.5–7.9","8.0+")))) | Z5: =IF(F5="","Blank",F5)
A6: M 7.3 - Alaska Peninsula | B6: 7.3 | C6: 16/07/2023 06:48 | D6: 0 | E6: 5 | G6: 1 | H6: 820 | I6: at | J6: 79 | K6: 0.879451 | L6: 172.8 | M6: Mi | N6: 21 | O6: 54.49 | P6: -160.796 | Q6: Alaska Peninsula | T6: =DATE(MID(C6,7,4),MID(C6,4,2),MID(C6,1,2))+TIME(MID(C6,12,2),MID(C6,15,2),0) | U6: =IF(ISNUMBER(VALUE(MID(A6,7,1))),"Distance-prefix pattern","Named-region pattern") | V6: =LOWER(M6) | W6: =IF(COUNTIFS($A$2:$A$1001,A6,$C$2:$C$1001,C6)>1,"Duplicate","Unique") | X6: =YEAR(T6) | Y6: =IF(B6<6.5,"<6.5",IF(B6<7,"6.5–6.9",IF(B6<7.5,"7.0–7.4",IF(B6<8,"7.5–7.9","8.0+")))) | Z6: =IF(F6="","Blank",F6)
A7: M 6.6 - 277 km NNE of Codrington, Antigua and Barbuda | B7: 6.6 | C7: 10/07/2023 20:28 | D7: 5 | E7: 4 | F7: green | G7: 1 | H7: 802 | I7: us | J7: 95 | K7: 2.454 | L7: 37 | M7: mww | N7: 10 | O7: 20.0196 | P7: -61.0955 | Q7: Codrington, Antigua and Barbuda | T7: =DATE(MID(C7,7,4),MID(C7,4,2),MID(C7,1,2))+TIME(MID(C7,12,2),MID(C7,15,2),0) | U7: =IF(ISNUMBER(VALUE(MID(A7,7,1))),"Distance-prefix pattern","Named-region pattern") | V7: =LOWER(M7) | W7: =IF(COUNTIFS($A$2:$A$1001,A7,$C$2:$C$1001,C7)>1,"Duplicate","Unique") | X7: =YEAR(T7) | Y7: =IF(B7<6.5,"<6.5",IF(B7<7,"6.5–6.9",IF(B7<7.5,"7.0–7.4",IF(B7<8,"7.5–7.9","8.0+")))) | Z7: =IF(F7="","Blank",F7)
A8: M 6.9 - Tonga | B8: 6.9 | C8: 02/07/2023 10:27 | D8: 4 | E8: 4 | F8: green | G8: 1 | H8: 741 | I8: us | J8: 136 | K8: 1.179 | L8: 23 | M8: mww | N8: 229 | O8: -17.853 | P8: -174.937 | Q8: Tonga | T8: =DATE(MID(C8,7,4),MID(C8,4,2),MID(C8,1,2))+TIME(MID(C8,12,2),MID(C8,15,2),0) | U8: =IF(ISNUMBER(VALUE(MID(A8,7,1))),"Distance-prefix pattern","Named-region pattern") | V8: =LOWER(M8) | W8: =IF(COUNTIFS($A$2:$A$1001,A8,$C$2:$C$1001,C8)>1,"Duplicate","Unique") | X8: =YEAR(T8) | Y8: =IF(B8<6.5,"<6.5",IF(B8<7,"6.5–6.9",IF(B8<7.5,"7.0–7.4",IF(B8<8,"7.5–7.9","8.0+")))) | Z8: =IF(F8="","Blank",F8)
A9: M 7.2 - south of the Fiji Islands | B9: 7.2 | C9: 15/06/2023 18:06 | D9: 8 | E9: 6 | F9: green | G9: 1 | H9: 804 | I9: us | J9: 85 | K9: 2.59 | L9: 24 | M9: mww | N9: 167.404 | O9: -22.9824 | P9: -177.208 | Q9: the Fiji Islands | T9: =DATE(MID(C9,7,4),MID(C9,4,2),MID(C9,1,2))+TIME(MID(C9,12,2),MID(C9,15,2),0) | U9: =IF(ISNUMBER(VALUE(MID(A9,7,1))),"Distance-prefix pattern","Named-region pattern") | V9: =LOWER(M9) | W9: =IF(COUNTIFS($A$2:$A$1001,A9,$C$2:$C$1001,C9)>1,"Duplicate","Unique") | X9: =YEAR(T9) | Y9: =IF(B9<6.5,"<6.5",IF(B9<7,"6.5–6.9",IF(B9<7.5,"7.0–7.4",IF(B9<8,"7.5–7.9","8.0+")))) | Z9: =IF(F9="","Blank",F9)
A10: M 6.6 - Panama-Colombia border region | B10: 6.6 | C10: 25/05/2023 03:05 | D10: 6 | E10: 6 | F10: green | G10: 1 | H10: 733 | I10: us | J10: 50 | K10: 2.163 | L10: 129 | M10: mww | N10: 10 | O10: 8.8894 | P10: -77.1231 | Q10: Panama-Colombia border region | S10: Colombia | T10: =DATE(MID(C10,7,4),MID(C10,4,2),MID(C10,1,2))+TIME(MID(C10,12,2),MID(C10,15,2),0) | U10: =IF(ISNUMBER(VALUE(MID(A10,7,1))),"Distance-prefix pattern","Named-region pattern") | V10: =LOWER(M10) | W10: =IF(COUNTIFS($A$2:$A$1001,A10,$C$2:$C$1001,C10)>1,"Duplicate","Unique") | X10: =YEAR(T10) | Y10: =IF(B10<6.5,"<6.5",IF(B10<7,"6.5–6.9",IF(B10<7.5,"7.0–7.4",IF(B10<8,"7.5–7.9","8.0+")))) | Z10: =IF(F10="","Blank",F10)
A11: M 7.1 - southeast of the Loyalty Islands | B11: 7.1 | C11: 20/05/2023 01:51 | D11: 3 | E11: 4 | F11: green | G11: 1 | H11: 777 | I11: us | J11: 98 | K11: 2.812 | L11: 56 | M11: mww | N11: 35.981 | O11: -23.0622 | P11: 170.456 | Q11: the Loyalty Islands | T11: =DATE(MID(C11,7,4),MID(C11,4,2),MID(C11,1,2))+TIME(MID(C11,12,2),MID(C11,15,2),0) | U11: =IF(ISNUMBER(VALUE(MID(A11,7,1))),"Distance-prefix pattern","Named-region pattern") | V11: =LOWER(M11) | W11: =IF(COUNTIFS($A$2:$A$1001,A11,$C$2:$C$1001,C11)>1,"Duplicate","Unique") | X11: =YEAR(T11) | Y11: =IF(B11<6.5,"<6.5",IF(B11<7,"6.5–6.9",IF(B11<7.5,"7.0–7.4",IF(B11<8,"7.5–7.9","8.0+")))) | Z11: =IF(F11="","Blank",F11)
A12: M 7.7 - southeast of the Loyalty Islands | B12: 7.7 | C12: 19/05/2023 02:57 | D12: 5 | E12: 4 | F12: green | G12: 1 | H12: 927 | I12: us | J12: 277 | K12: 3.111 | L12: 15 | M12: mww | N12: 18.027 | O12: -23.2286 | P12: 170.694 | Q12: the Loyalty Islands | T12: =DATE(MID(C12,7,4),MID(C12,4,2),MID(C12,1,2))+TIME(MID(C12,12,2),MID(C12,15,2),0) | U12: =IF(ISNUMBER(VALUE(MID(A12,7,1))),"Distance-prefix pattern","Named-region pattern") | V12: =LOWER(M12) | W12: =IF(COUNTIFS($A$2:$A$1001,A12,$C$2:$C$1001,C12)>1,"Duplicate","Unique") | X12: =YEAR(T12) | Y12: =IF(B12<6.5,"<6.5",IF(B12<7,"6.5–6.9",IF(B12<7.5,"7.0–7.4",IF(B12<8,"7.5–7.9","8.0+")))) | Z12: =IF(F12="","Blank",F12)
A13: M 7.6 - 95 km WNW of Hihifo, Tonga | B13: 7.6 | C13: 10/05/2023 16:02 | D13: 8 | E13: 6 | F13: green | G13: 1 | H13: 907 | I13: us | J13: 111 | K13: 3.631 | L13: 17 | M13: mww | N13: 210.097 | O13: -15.6002 | P13: -174.608 | Q13: Hihifo, Tonga | T13: =DATE(MID(C13,7,4),MID(C13,4,2),MID(C13,1,2))+TIME(MID(C13,12,2),MID(C13,15,2),0) | U13: =IF(ISNUMBER(VALUE(MID(A13,7,1))),"Distance-prefix pattern","Named-region pattern") | V13: =LOWER(M13) | W13: =IF(COUNTIFS($A$2:$A$1001,A13,$C$2:$C$1001,C13)>1,"Duplicate","Unique") | X13: =YEAR(T13) | Y13: =IF(B13<6.5,"<6.5",IF(B13<7,"6.5–6.9",IF(B13<7.5,"7.0–7.4",IF(B13<8,"7.5–7.9","8.0+")))) | Z13: =IF(F13="","Blank",F13)
A14: M 6.6 - south of the Fiji Islands | B14: 6.6 | C14: 28/04/2023 03:13 | D14: 0 | E14: 2 | F14: green | G14: 0 | H14: 670 | I14: us | J14: 52 | K14: 5.123 | L14: 50 | M14: mww | N14: 598.467 | O14: -25.2657 | P14: 178.424 | Q14: the Fiji Islands | T14: =DATE(MID(C14,7,4),MID(C14,4,2),MID(C14,1,2))+TIME(MID(C14,12,2),MID(C14,15,2),0) | U14: =IF(ISNUMBER(VALUE(MID(A14,7,1))),"Distance-prefix pattern","Named-region pattern") | V14: =LOWER(M14) | W14: =IF(COUNTIFS($A$2:$A$1001,A14,$C$2:$C$1001,C14)>1,"Duplicate","Unique") | X14: =YEAR(T14) | Y14: =IF(B14<6.5,"<6.5",IF(B14<7,"6.5–6.9",IF(B14<7.5,"7.0–7.4",IF(B14<8,"7.5–7.9","8.0+")))) | Z14: =IF(F14="","Blank",F14)
A15: M 7.1 - 170 km SSE of Teluk Dalam, Indonesia | B15: 7.1 | C15: 24/04/2023 20:00 | D15: 9 | E15: 7 | F15: green | G15: 0 | H15: 838 | I15: us | J15: 70 | K15: 2.282 | L15: 58 | M15: mww | N15: 15.462 | O15: -0.781 | P15: 98.5339 | Q15: Teluk Dalam, Indonesia | S15: Indonesia | T15: =DATE(MID(C15,7,4),MID(C15,4,2),MID(C15,1,2))+TIME(MID(C15,12,2),MID(C15,15,2),0) | U15: =IF(ISNUMBER(VALUE(MID(A15,7,1))),"Distance-prefix pattern","Named-region pattern") | V15: =LOWER(M15) | W15: =IF(COUNTIFS($A$2:$A$1001,A15,$C$2:$C$1001,C15)>1,"Duplicate","Unique") | X15: =YEAR(T15) | Y15: =IF(B15<6.5,"<6.5",IF(B15<7,"6.5–6.9",IF(B15<7.5,"7.0–7.4",IF(B15<8,"7.5–7.9","8.0+")))) | Z15: =IF(F15="","Blank",F15)
A16: M 7.1 - Kermadec Islands, New Zealand | B16: 7.1 | C16: 24/04/2023 00:41 | D16: 8 | E16: 7 | F16: green | G16: 1 | H16: 777 | I16: us | J16: 126 | K16: 0.708 | L16: 23 | M16: mww | N16: 43.063 | O16: -30.0249 | P16: -177.897 | Q16: Kermadec Islands, New Zealand | T16: =DATE(MID(C16,7,4),MID(C16,4,2),MID(C16,1,2))+TIME(MID(C16,12,2),MID(C16,15,2),0) | U16: =IF(ISNUMBER(VALUE(MID(A16,7,1))),"Distance-prefix pattern","Named-region pattern") | V16: =LOWER(M16) | W16: =IF(COUNTIFS($A$2:$A$1001,A16,$C$2:$C$1001,C16)>1,"Duplicate","Unique") | X16: =YEAR(T16) | Y16: =IF(B16<6.5,"<6.5",IF(B16<7,"6.5–6.9",IF(B16<7.5,"7.0–7.4",IF(B16<8,"7.5–7.9","8.0+")))) | Z16: =IF(F16="","Blank",F16)
A17: M 6.7 - south of the Fiji Islands | B17: 6.7 | C17: 18/04/2023 04:31 | D17: 0 | E17: 3 | F17: green | G17: 1 | H17: 691 | I17: us | J17: 166 | K17: 4.719 | L17: 10 | M17: mww | N17: 595.854 | O17: -22.2844 | P17: 179.391 | Q17: the Fiji Islands | T17: =DATE(MID(C17,7,4),MID(C17,4,2),MID(C17,1,2))+TIME(MID(C17,12,2),MID(C17,15,2),0) | U17: =IF(ISNUMBER(VALUE(MID(A17,7,1))),"Distance-prefix pattern","Named-region pattern") | V17: =LOWER(M17) | W17: =IF(COUNTIFS($A$2:$A$1001,A17,$C$2:$C$1001,C17)>1,"Duplicate","Unique") | X17: =YEAR(T17) | Y17: =IF(B17<6.5,"<6.5",IF(B17<7,"6.5–6.9",IF(B17<7.5,"7.0–7.4",IF(B17<8,"7.5–7.9","8.0+")))) | Z17: =IF(F17="","Blank",F17)
A18: M 7.0 - 96 km N of Tuban, Indonesia | B18: 7 | C18: 14/04/2023 09:55 | D18: 5 | E18: 3 | F18: green | G18: 0 | H18: 818 | I18: us | J18: 131 | K18: 1.881 | L18: 31 | M18: mww | N18: 594.028 | O18: -6.0255 | P18: 112.033 | Q18: Tuban, Indonesia | S18: Indonesia | T18: =DATE(MID(C18,7,4),MID(C18,4,2),MID(C18,1,2))+TIME(MID(C18,12,2),MID(C18,15,2),0) | U18: =IF(ISNUMBER(VALUE(MID(A18,7,1))),"Distance-prefix pattern","Named-region pattern") | V18: =LOWER(M18) | W18: =IF(COUNTIFS($A$2:$A$1001,A18,$C$2:$C$1001,C18)>1,"Duplicate","Unique") | X18: =YEAR(T18) | Y18: =IF(B18<6.5,"<6.5",IF(B18<7,"6.5–6.9",IF(B18<7.5,"7.0–7.4",IF(B18<8,"7.5–7.9","8.0+")))) | Z18: =IF(F18="","Blank",F18)
A19: M 6.5 - near the east coast of the Kamchatka Peninsula, Russia | B19: 6.5 | C19: 03/04/2023 03:06 | D19: 7 | E19: 6 | F19: yellow | G19: 1 | H19: 655 | I19: us | J19: 104 | K19: 0.266 | L19: 30 | M19: mww | N19: 105.631 | O19: 52.7772 | P19: 158.484 | Q19: the Kamchatka Peninsula, Russia | R19: Asia | S19: Russian Federation (the) | T19: =DATE(MID(C19,7,4),MID(C19,4,2),MID(C19,1,2))+TIME(MID(C19,12,2),MID(C19,15,2),0) | U19: =IF(ISNUMBER(VALUE(MID(A19,7,1))),"Distance-prefix pattern","Named-region pattern") | V19: =LOWER(M19) | W19: =IF(COUNTIFS($A$2:$A$1001,A19,$C$2:$C$1001,C19)>1,"Duplicate","Unique") | X19: =YEAR(T19) | Y19: =IF(B19<6.5,"<6.5",IF(B19<7,"6.5–6.9",IF(B19<7.5,"7.0–7.4",IF(B19<8,"7.5–7.9","8.0+")))) | Z19: =IF(F19="","Blank",F19)
A20: M 7.0 - New Guinea, Papua New Guinea | B20: 7 | C20: 02/04/2023 18:04 | D20: 7 | E20: 7 | F20: green | G20: 1 | H20: 781 | I20: us | J20: 105 | K20: 6.45 | L20: 31 | M20: mww | N20: 62.603 | O20: -4.2924 | P20: 143.155 | Q20: New Guinea, Papua New Guinea | R20: Asia | S20: Papua New Guinea | T20: =DATE(MID(C20,7,4),MID(C20,4,2),MID(C20,1,2))+TIME(MID(C20,12,2),MID(C20,15,2),0) | U20: =IF(ISNUMBER(VALUE(MID(A20,7,1))),"Distance-prefix pattern","Named-region pattern") | V20: =LOWER(M20) | W20: =IF(COUNTIFS($A$2:$A$1001,A20,$C$2:$C$1001,C20)>1,"Duplicate","Unique") | X20: =YEAR(T20) | Y20: =IF(B20<6.5,"<6.5",IF(B20<7,"6.5–6.9",IF(B20<7.5,"7.0–7.4",IF(B20<8,"7.5–7.9","8.0+")))) | Z20: =IF(F20="","Blank",F20)
A21: M 6.5 - 84 km NNW of San Antonio de los Cobres, Argentina | B21: 6.5 | C21: 22/03/2023 16:00 | D21: 4 | E21: 4 | F21: green | G21: 0 | H21: 656 | I21: us | J21: 97 | K21: 1.622 | L21: 33 | M21: mww | N21: 209.976 | O21: -23.4797 | P21: -66.5108 | Q21: San Antonio de los Cobres, Argentina | R21: South America | S21: Argentina | T21: =DATE(MID(C21,7,4),MID(C21,4,2),MID(C21,1,2))+TIME(MID(C21,12,2),MID(C21,15,2),0) | U21: =IF(ISNUMBER(VALUE(MID(A21,7,1))),"Distance-prefix pattern","Named-region pattern") | V21: =LOWER(M21) | W21: =IF(COUNTIFS($A$2:$A$1001,A21,$C$2:$C$1001,C21)>1,"Duplicate","Unique") | X21: =YEAR(T21) | Y21: =IF(B21<6.5,"<6.5",IF(B21<7,"6.5–6.9",IF(B21<7.5,"7.0–7.4",IF(B21<8,"7.5–7.9","8.0+")))) | Z21: =IF(F21="","Blank",F21)
A22: M 6.5 - 40 km SSE of Jurm, Afghanistan | B22: 6.5 | C22: 21/03/2023 16:47 | D22: 7 | E22: 5 | F22: green | G22: 0 | H22: 1350 | I22: us | J22: 134 | K22: 2.53 | L22: 13 | M22: mww | N22: 187.589 | O22: 36.5227 | P22: 70.9787 | Q22: Jurm, Afghanistan | R22: Asia | S22: Afghanistan | T22: =DATE(MID(C22,7,4),MID(C22,4,2),MID(C22,1,2))+TIME(MID(C22,12,2),MID(C22,15,2),0) | U22: =IF(ISNUMBER(VALUE(MID(A22,7,1))),"Distance-prefix pattern","Named-region pattern") | V22: =LOWER(M22) | W22: =IF(COUNTIFS($A$2:$A$1001,A22,$C$2:$C$1001,C22)>1,"Duplicate","Unique") | X22: =YEAR(T22) | Y22: =IF(B22<6.5,"<6.5",IF(B22<7,"6.5–6.9",IF(B22<7.5,"7.0–7.4",IF(B22<8,"7.5–7.9","8.0+")))) | Z22: =IF(F22="","Blank",F22)
A23: M 6.8 - near the coast of Ecuador | B23: 6.8 | C23: 18/03/2023 17:12 | D23: 9 | E23: 7 | F23: orange | G23: 1 | H23: 1159 | I23: us | J23: 152 | K23: 0.709 | L23: 28 | M23: mww | N23: 65.842 | O23: -2.851 | P23: -79.8001 | Q23: Ecuador | R23: South America | S23: Ecuador | T23: =DATE(MID(C23,7,4),MID(C23,4,2),MID(C23,1,2))+TIME(MID(C23,12,2),MID(C23,15,2),0) | U23: =IF(ISNUMBER(VALUE(MID(A23,7,1))),"Distance-prefix pattern","Named-region pattern") | V23: =LOWER(M23) | W23: =IF(COUNTIFS($A$2:$A$1001,A23,$C$2:$C$1001,C23)>1,"Duplicate","Unique") | X23: =YEAR(T23) | Y23: =IF(B23<6.5,"<6.5",IF(B23<7,"6.5–6.9",IF(B23<7.5,"7.0–7.4",IF(B23<8,"7.5–7.9","8.0+")))) | Z23: =IF(F23="","Blank",F23)
A24: M 7.0 - Kermadec Islands region | B24: 7 | C24: 16/03/2023 00:56 | D24: 8 | E24: 5 | F24: green | G24: 1 | H24: 756 | I24: us | J24: 116 | K24: 1.789 | L24: 22 | M24: mww | N24: 22.065 | O24: -30.1147 | P24: -176.112 | Q24: Kermadec Islands region | T24: =DATE(MID(C24,7,4),MID(C24,4,2),MID(C24,1,2))+TIME(MID(C24,12,2),MID(C24,15,2),0) | U24: =IF(ISNUMBER(VALUE(MID(A24,7,1))),"Distance-prefix pattern","Named-region pattern") | V24: =LOWER(M24) | W24: =IF(COUNTIFS($A$2:$A$1001,A24,$C$2:$C$1001,C24)>1,"Duplicate","Unique") | X24: =YEAR(T24) | Y24: =IF(B24<6.5,"<6.5",IF(B24<7,"6.5–6.9",IF(B24<7.5,"7.0–7.4",IF(B24<8,"7.5–7.9","8.0+")))) | Z24: =IF(F24="","Blank",F24)
A25: M 6.9 - Kermadec Islands, New Zealand | B25: 6.9 | C25: 04/03/2023 06:41 | D25: 5 | E25: 5 | F25: green | G25: 1 | H25: 735 | I25: us | J25: 108 | K25: 0.784 | L25: 18 | M25: mww | N25: 205.681 | O25: -29.4748 | P25: -178.787 | Q25: Kermadec Islands, New Zealand | T25: =DATE(MID(C25,7,4),MID(C25,4,2),MID(C25,1,2))+TIME(MID(C25,12,2),MID(C25,15,2),0) | U25: =IF(ISNUMBER(VALUE(MID(A25,7,1))),"Distance-prefix pattern","Named-region pattern") | V25: =LOWER(M25) | W25: =IF(COUNTIFS($A$2:$A$1001,A25,$C$2:$C$1001,C25)>1,"Duplicate","Unique") | X25: =YEAR(T25) | Y25: =IF(B25<6.5,"<6.5",IF(B25<7,"6.5–6.9",IF(B25<7.5,"7.0–7.4",IF(B25<8,"7.5–7.9","8.0+")))) | Z25: =IF(F25="","Blank",F25)
A26: M 6.5 - 86 km WSW of Port-Olry, Vanuatu | B26: 6.5 | C26: 02/03/2023 18:04 | D26: 7 | E26: 6 | F26: green | G26: 1 | H26: 653 | I26: us | J26: 66 | K26: 5.483 | L26: 45 | M26: mww | N26: 10 | O26: -15.3597 | P26: 166.385 | Q26: Port-Olry, Vanuatu | T26: =DATE(MID(C26,7,4),MID(C26,4,2),MID(C26,1,2))+TIME(MID(C26,12,2),MID(C26,15,2),0) | U26: =IF(ISNUMBER(VALUE(MID(A26,7,1))),"Distance-prefix pattern","Named-region pattern") | V26: =LOWER(M26) | W26: =IF(COUNTIFS($A$2:$A$1001,A26,$C$2:$C$1001,C26)>1,"Duplicate","Unique") | X26: =YEAR(T26) | Y26: =IF(B26<6.5,"<6.5",IF(B26<7,"6.5–6.9",IF(B26<7.5,"7.0–7.4",IF(B26<8,"7.5–7.9","8.0+")))) | Z26: =IF(F26="","Blank",F26)
A27: M 6.5 - 108 km NW of Kimbe, Papua New Guinea | B27: 6.5 | C27: 01/03/2023 05:36 | D27: 4 | E27: 2 | F27: green | G27: 1 | H27: 652 | I27: us | J27: 115 | K27: 2.739 | L27: 20 | M27: mww | N27: 598.925 | O27: -4.8138 | P27: 149.487 | Q27: Kimbe, Papua New Guinea | S27: Papua New Guinea | T27: =DATE(MID(C27,7,4),MID(C27,4,2),MID(C27,1,2))+TIME(MID(C27,12,2),MID(C27,15,2),0) | U27: =IF(ISNUMBER(VALUE(MID(A27,7,1))),"Distance-prefix pattern","Named-region pattern") | V27: =LOWER(M27) | W27: =IF(COUNTIFS($A$2:$A$1001,A27,$C$2:$C$1001,C27)>1,"Duplicate","Unique") | X27: =YEAR(T27) | Y27: =IF(B27<6.5,"<6.5",IF(B27<7,"6.5–6.9",IF(B27<7.5,"7.0–7.4",IF(B27<8,"7.5–7.9","8.0+")))) | Z27: =IF(F27="","Blank",F27)
A28: M 6.8 - 67 km W of Murghob, Tajikistan | B28: 6.8 | C28: 23/02/2023 00:37 | D28: 9 | E28: 7 | F28: green | G28: 0 | H28: 737 | I28: us | J28: 128 | K28: 1.783 | L28: 20 | M28: mww | N28: 20.522 | O28: 38.0726 | P28: 73.2077 | Q28: Murghob, Tajikistan | R28: Asia | S28: Tajikistan | T28: =DATE(MID(C28,7,4),MID(C28,4,2),MID(C28,1,2))+TIME(MID(C28,12,2),MID(C28,15,2),0) | U28: =IF(ISNUMBER(VALUE(MID(A28,7,1))),"Distance-prefix pattern","Named-region pattern") | V28: =LOWER(M28) | W28: =IF(COUNTIFS($A$2:$A$1001,A28,$C$2:$C$1001,C28)>1,"Duplicate","Unique") | X28: =YEAR(T28) | Y28: =IF(B28<6.5,"<6.5",IF(B28<7,"6.5–6.9",IF(B28<7.5,"7.0–7.4",IF(B28<8,"7.5–7.9","8.0+")))) | Z28: =IF(F28="","Blank",F28)
A29: M 7.5 - 4 km SSE of Ekinözü, Turkey | B29: 7.5 | C29: 06/02/2023 10:24 | D29: 9 | E29: 9 | F29: orange | G29: 0 | H29: 1411 | I29: us | J29: 135 | K29: 0.85 | L29: 17 | M29: mww | N29: 10 | O29: 38.0235 | P29: 37.203 | Q29: Ekinözü, Turkey | R29: Asia | S29: Turkiye | T29: =DATE(MID(C29,7,4),MID(C29,4,2),MID(C29,1,2))+TIME(MID(C29,12,2),MID(C29,15,2),0) | U29: =IF(ISNUMBER(VALUE(MID(A29,7,1))),"Distance-prefix pattern","Named-region pattern") | V29: =LOWER(M29) | W29: =IF(COUNTIFS($A$2:$A$1001,A29,$C$2:$C$1001,C29)>1,"Duplicate","Unique") | X29: =YEAR(T29) | Y29: =IF(B29<6.5,"<6.5",IF(B29<7,"6.5–6.9",IF(B29<7.5,"7.0–7.4",IF(B29<8,"7.5–7.9","8.0+")))) | Z29: =IF(F29="","Blank",F29)
A30: M 6.7 - 18 km ESE of Nurdağı, Turkey | B30: 6.7 | C30: 06/02/2023 01:28 | D30: 9 | E30: 8 | F30: yellow | G30: 0 | H30: 800 | I30: us | J30: 108 | K30: 0.218 | L30: 44 | M30: mww | N30: 14.497 | O30: 37.4135 | P30: 36.8306 | Q30: Nurdağı, Turkey | R30: Asia | S30: Turkiye | T30: =DATE(MID(C30,7,4),MID(C30,4,2),MID(C30,1,2))+TIME(MID(C30,12,2),MID(C30,15,2),0) | U30: =IF(ISNUMBER(VALUE(MID(A30,7,1))),"Distance-prefix pattern","Named-region pattern") | V30: =LOWER(M30) | W30: =IF(COUNTIFS($A$2:$A$1001,A30,$C$2:$C$1001,C30)>1,"Duplicate","Unique") | X30: =YEAR(T30) | Y30: =IF(B30<6.5,"<6.5",IF(B30<7,"6.5–6.9",IF(B30<7.5,"7.0–7.4",IF(B30<8,"7.5–7.9","8.0+")))) | Z30: =IF(F30="","Blank",F30)
A31: M 7.8 - Central Turkey | B31: 7.8 | C31: 06/02/2023 01:17 | D31: 9 | E31: 9 | F31: red | G31: 0 | H31: 2910 | I31: us | J31: 118 | K31: 1.919 | L31: 32 | M31: mww | N31: 17.925 | O31: 37.2012 | P31: 36.9997 | Q31: Central Turkey | R31: Asia | S31: Turkiye | T31: =DATE(MID(C31,7,4),MID(C31,4,2),MID(C31,1,2))+TIME(MID(C31,12,2),MID(C31,15,2),0) | U31: =IF(ISNUMBER(VALUE(MID(A31,7,1))),"Distance-prefix pattern","Named-region pattern") | V31: =LOWER(M31) | W31: =IF(COUNTIFS($A$2:$A$1001,A31,$C$2:$C$1001,C31)>1,"Duplicate","Unique") | X31: =YEAR(T31) | Y31: =IF(B31<6.5,"<6.5",IF(B31<7,"6.5–6.9",IF(B31<7.5,"7.0–7.4",IF(B31<8,"7.5–7.9","8.0+")))) | Z31: =IF(F31="","Blank",F31)
A32: M 6.8 - | B32: 6.8 | C32: 20/01/2023 22:09 | D32: 4 | E32: 3 | F32: green | G32: 0 | H32: 718 | I32: us | J32: 60 | K32: 5.129 | L32: 61 | M32: mww | N32: 610.671 | O32: -26.7209 | P32: -63.0394 | R32: South America | S32: Argentina | T32: =DATE(MID(C32,7,4),MID(C32,4,2),MID(C32,1,2))+TIME(MID(C32,12,2),MID(C32,15,2),0) | U32: =IF(ISNUMBER(VALUE(MID(A32,7,1))),"Distance-prefix pattern","Named-region pattern") | V32: =LOWER(M32) | W32: =IF(COUNTIFS($A$2:$A$1001,A32,$C$2:$C$1001,C32)>1,"Duplicate","Unique") | X32: =YEAR(T32) | Y32: =IF(B32<6.5,"<6.5",IF(B32<7,"6.5–6.9",IF(B32<7.5,"7.0–7.4",IF(B32<8,"7.5–7.9","8.0+")))) | Z32: =IF(F32="","Blank",F32)
A33: M 7.0 - 153 km NW of Tobelo, Indonesia | B33: 7 | C33: 18/01/2023 06:06 | D33: 3 | E33: 5 | F33: green | G33: 1 | H33: 756 | I33: us | J33: 130 | K33: 1.974 | L33: 17 | M33: mwc | N33: 28.566 | O33: 2.7401 | P33: 127.051 | Q33: Tobelo, Indonesia | S33: Indonesia | T33: =DATE(MID(C33,7,4),MID(C33,4,2),MID(C33,1,2))+TIME(MID(C33,12,2),MID(C33,15,2),0) | U33: =IF(ISNUMBER(VALUE(MID(A33,7,1))),"Distance-prefix pattern","Named-region pattern") | V33: =LOWER(M33) | W33: =IF(COUNTIFS($A$2:$A$1001,A33,$C$2:$C$1001,C33)>1,"Duplicate","Unique") | X33: =YEAR(T33) | Y33: =IF(B33<6.5,"<6.5",IF(B33<7,"6.5–6.9",IF(B33<7.5,"7.0–7.4",IF(B33<8,"7.5–7.9","8.0+")))) | Z33: =IF(F33="","Blank",F33)
A34: M 7.6 - Pulau Pulau Tanimbar, Indonesia | B34: 7.6 | C34: 09/01/2023 17:47 | D34: 5 | E34: 7 | F34: green | G34: 0 | H34: 957 | I34: us | J34: 114 | K34: 1.575 | L34: 21 | M34: mww | N34: 105.249 | O34: -7.0852 | P34: 130.039 | Q34: Pulau Pulau Tanimbar, Indonesia | S34: Indonesia | T34: =DATE(MID(C34,7,4),MID(C34,4,2),MID(C34,1,2))+TIME(MID(C34,12,2),MID(C34,15,2),0) | U34: =IF(ISNUMBER(VALUE(MID(A34,7,1))),"Distance-prefix pattern","Named-region pattern") | V34: =LOWER(M34) | W34: =IF(COUNTIFS($A$2:$A$1001,A34,$C$2:$C$1001,C34)>1,"Duplicate","Unique") | X34: =YEAR(T34) | Y34: =IF(B34<6.5,"<6.5",IF(B34<7,"6.5–6.9",IF(B34<7.5,"7.0–7.4",IF(B34<8,"7.5–7.9","8.0+")))) | Z34: =IF(F34="","Blank",F34)
A35: M 7.0 - Vanuatu | B35: 7 | C35: 08/01/2023 12:32 | D35: 8 | E35: 7 | F35: green | G35: 1 | H35: 768 | I35: us | J35: 116 | K35: 6.096 | L35: 36 | M35: mww | N35: 29 | O35: -14.9383 | P35: 166.878 | Q35: Vanuatu | S35: Vanuatu | T35: =DATE(MID(C35,7,4),MID(C35,4,2),MID(C35,1,2))+TIME(MID(C35,12,2),MID(C35,15,2),0) | U35: =IF(ISNUMBER(VALUE(MID(A35,7,1))),"Distance-prefix pattern","Named-region pattern") | V35: =LOWER(M35) | W35: =IF(COUNTIFS($A$2:$A$1001,A35,$C$2:$C$1001,C35)>1,"Duplicate","Unique") | X35: =YEAR(T35) | Y35: =IF(B35<6.5,"<6.5",IF(B35<7,"6.5–6.9",IF(B35<7.5,"7.0–7.4",IF(B35<8,"7.5–7.9","8.0+")))) | Z35: =IF(F35="","Blank",F35)
A36: M 6.8 - 109 km NE of Hihifo, Tonga | B36: 6.8 | C36: 04/12/2022 19:24 | D36: 5 | E36: 5 | F36: green | G36: 1 | H36: 720 | I36: us | J36: 152 | K36: 2.587 | L36: 26 | M36: mww | N36: 38 | O36: -15.3983 | P36: -172.968 | Q36: Hihifo, Tonga | T36: =DATE(MID(C36,7,4),MID(C36,4,2),MID(C36,1,2))+TIME(MID(C36,12,2),MID(C36,15,2),0) | U36: =IF(ISNUMBER(VALUE(MID(A36,7,1))),"Distance-prefix pattern","Named-region pattern") | V36: =LOWER(M36) | W36: =IF(COUNTIFS($A$2:$A$1001,A36,$C$2:$C$1001,C36)>1,"Duplicate","Unique") | X36: =YEAR(T36) | Y36: =IF(B36<6.5,"<6.5",IF(B36<7,"6.5–6.9",IF(B36<7.5,"7.0–7.4",IF(B36<8,"7.5–7.9","8.0+")))) | Z36: =IF(F36="","Blank",F36)
A37: M 7.0 - 18 km SW of Malango, Solomon Islands | B37: 7 | C37: 22/11/2022 02:03 | D37: 8 | E37: 7 | F37: green | G37: 1 | H37: 768 | I37: us | J37: 117 | K37: 0.509 | L37: 17 | M37: mww | N37: 14 | O37: -9.7963 | P37: 159.596 | Q37: Malango, Solomon Islands | R37: Oceania | S37: Solomon Islands | T37: =DATE(MID(C37,7,4),MID(C37,4,2),MID(C37,1,2))+TIME(MID(C37,12,2),MID(C37,15,2),0) | U37: =IF(ISNUMBER(VALUE(MID(A37,7,1))),"Distance-prefix pattern","Named-region pattern") | V37: =LOWER(M37) | W37: =IF(COUNTIFS($A$2:$A$1001,A37,$C$2:$C$1001,C37)>1,"Duplicate","Unique") | X37: =YEAR(T37) | Y37: =IF(B37<6.5,"<6.5",IF(B37<7,"6.5–6.9",IF(B37<7.5,"7.0–7.4",IF(B37<8,"7.5–7.9","8.0+")))) | Z37: =IF(F37="","Blank",F37)
A38: M 6.9 - 204 km SW of Bengkulu, Indonesia | B38: 6.9 | C38: 18/11/2022 13:37 | D38: 4 | E38: 4 | F38: green | G38: 0 | H38: 735 | I38: us | J38: 99 | K38: 2.229 | L38: 34 | M38: mww | N38: 25 | O38: -4.9559 | P38: 100.738 | Q38: Bengkulu, Indonesia | T38: =DATE(MID(C38,7,4),MID(C38,4,2),MID(C38,1,2))+TIME(MID(C38,12,2),MID(C38,15,2),0) | U38: =IF(ISNUMBER(VALUE(MID(A38,7,1))),"Distance-prefix pattern","Named-region pattern") | V38: =LOWER(M38) | W38: =IF(COUNTIFS($A$2:$A$1001,A38,$C$2:$C$1001,C38)>1,"Duplicate","Unique") | X38: =YEAR(T38) | Y38: =IF(B38<6.5,"<6.5",IF(B38<7,"6.5–6.9",IF(B38<7.5,"7.0–7.4",IF(B38<8,"7.5–7.9","8.0+")))) | Z38: =IF(F38="","Blank",F38)
A39: M 7.0 - | B39: 7 | C39: 12/11/2022 07:09 | D39: 3 | E39: 3 | F39: green | G39: 1 | H39: 755 | I39: us | J39: 147 | K39: 3.125 | L39: 18 | M39: mww | N39: 579 | O39: -20.0508 | P39: -178.346 | R39: Oceania | S39: Fiji | T39: =DATE(MID(C39,7,4),MID(C39,4,2),MID(C39,1,2))+TIME(MID(C39,12,2),MID(C39,15,2),0) | U39: =IF(ISNUMBER(VALUE(MID(A39,7,1))),"Distance-prefix pattern","Named-region pattern") | V39: =LOWER(M39) | W39: =IF(COUNTIFS($A$2:$A$1001,A39,$C$2:$C$1001,C39)>1,"Duplicate","Unique") | X39: =YEAR(T39) | Y39: =IF(B39<6.5,"<6.5",IF(B39<7,"6.5–6.9",IF(B39<7.5,"7.0–7.4",IF(B39<8,"7.5–7.9","8.0+")))) | Z39: =IF(F39="","Blank",F39)
A40: M 7.3 - 205 km ESE of Neiafu, Tonga | B40: 7.3 | C40: 11/11/2022 10:48 | D40: 5 | E40: 5 | F40: green | G40: 1 | H40: 833 | I40: us | J40: 149 | K40: 1.865 | L40: 21 | M40: mww | N40: 37 | O40: -19.2918 | P40: -172.129 | Q40: Neiafu, Tonga | T40: =DATE(MID(C40,7,4),MID(C40,4,2),MID(C40,1,2))+TIME(MID(C40,12,2),MID(C40,15,2),0) | U40: =IF(ISNUMBER(VALUE(MID(A40,7,1))),"Distance-prefix pattern","Named-region pattern") | V40: =LOWER(M40) | W40: =IF(COUNTIFS($A$2:$A$1001,A40,$C$2:$C$1001,C40)>1,"Duplicate","Unique") | X40: =YEAR(T40) | Y40: =IF(B40<6.5,"<6.5",IF(B40<7,"6.5–6.9",IF(B40<7.5,"7.0–7.4",IF(B40<8,"7.5–7.9","8.0+")))) | Z40: =IF(F40="","Blank",F40)
...

Sheet Task 1 - Exploration
A1: Task 1: Excel-Based Exploration
A3: Number of records | B3: =COUNTA(Data!A2:A1001)
A4: Number of columns | B4: =COUNTA(Data!1:1)-7
A5: Magnitude minimum | B5: =MIN(Data!B2:B1001)
A6: Magnitude maximum | B6: =MAX(Data!B2:B1001)
A7: Magnitude average | B7: =AVERAGE(Data!B2:B1001)
A8: Depth minimum | B8: =MIN(Data!N2:N1001)
A9: Depth maximum | B9: =MAX(Data!N2:N1001)
A10: Depth average | B10: =AVERAGE(Data!N2:N1001)
A13: Magnitude Type Counts (formula-driven)
A14: Mi | B14: =COUNTIF(Data!M$2:M$1001,A14)
A15: mb | B15: =COUNTIF(Data!M$2:M$1001,A15)
A16: md | B16: =COUNTIF(Data!M$2:M$1001,A16)
A17: ml | B17: =COUNTIF(Data!M$2:M$1001,A17)
A18: ms | B18: =COUNTIF(Data!M$2:M$1001,A18)
A19: mw | B19: =COUNTIF(Data!M$2:M$1001,A19)
A20: mwb | B20: =COUNTIF(Data!M$2:M$1001,A20)
A21: mwc | B21: =COUNTIF(Data!M$2:M$1001,A21)
A22: mww | B22: =COUNTIF(Data!M$2:M$1001,A22)
A26: Alert Level Counts (blank included)
A27: Blank | B27: =COUNTBLANK(Data!F$2:F$1001)
A28: green | B28: =COUNTIF(Data!F$2:F$1001,A28)
A29: yellow | B29: =COUNTIF(Data!F$2:F$1001,A29)
A30: orange | B30: =COUNTIF(Data!F$2:F$1001,A30)
A31: red | B31: =COUNTIF(Data!F$2:F$1001,A31)
A34: Magnitude Band Counts
A35: 6.5–6.9 | B35: =COUNTIF(Data!Y$2:Y$1001,A35)
A36: 7.0–7.4 | B36: =COUNTIF(Data!Y$2:Y$1001,A36)
A37: 7.5–7.9 | B37: =COUNTIF(Data!Y$2:Y$1001,A37)
A38: 8.0+ | B38: =COUNTIF(Data!Y$2:Y$1001,A38)

Sheet Task 2 - Quality Audit
A1: Task 2: Data Type and Quality Audit
A3: Column | B3: Data Type | C3: Quality / Audit Check | D3: Formula / Method | E3: Result | F3: Interpretation
A4: title | B4: text | C4: Title pattern audit | D4: =COUNTA(Data!A2:A1001) | E4: =COUNTA(Data!A2:A1001) | F4: Text values
A5: magnitude | B5: numeric | C5: Range | D5: =MIN(Data!B2:B1001)&" to "&MAX(Data!B2:B1001) | E5: =MIN(Data!B2:B1001)&" to "&MAX(Data!B2:B1001) | F5: Numeric
A6: date_time | B6: datetime (raw text) | C6: Confirm raw cell is text | D6: =ISNUMBER(Data!C2) | E6: =ISNUMBER(Data!C2) | F6: FALSE = raw value is text
A7: cdi | B7: numeric | C7: Numeric check | D7: =ISNUMBER(Data!D2) | E7: =ISNUMBER(Data!D2) | F7: TRUE/FALSE sample check
A8: mmi | B8: numeric | C8: Numeric check | D8: =ISNUMBER(Data!E2) | E8: =ISNUMBER(Data!E2) | F8: TRUE/FALSE sample check
A9: alert | B9: categorical | C9: Blank percentage | D9: =COUNTBLANK(Data!F2:F1001)/COUNTA(Data!A2:A1001) | E9: =COUNTBLANK(Data!F2:F1001)/COUNTA(Data!A2:A1001) | F9: Percent blank
A10: tsunami | B10: categorical | C10: Distinct flag values | D10: =COUNTA(Data!G2:G1001) | E10: =COUNTA(Data!G2:G1001) | F10: 0/1 event flag
A11: sig | B11: numeric | C11: Numeric check | D11: =ISNUMBER(Data!H2) | E11: =ISNUMBER(Data!H2) | F11: TRUE/FALSE sample check
A12: net | B12: categorical | C12: Distinct network codes | D12: =COUNTA(Data!I2:I1001) | E12: =COUNTA(Data!I2:I1001) | F12: Categorical code
A13: nst | B13: numeric | C13: Numeric check | D13: =ISNUMBER(Data!J2) | E13: =ISNUMBER(Data!J2) | F13: TRUE/FALSE sample check
A14: dmin | B14: numeric | C14: Numeric check | D14: =ISNUMBER(Data!K2) | E14: =ISNUMBER(Data!K2) | F14: TRUE/FALSE sample check
A15: gap | B15: numeric | C15: Numeric check | D15: =ISNUMBER(Data!L2) | E15: =ISNUMBER(Data!L2) | F15: TRUE/FALSE sample check
A16: magType | B16: categorical | C16: Casing normalization | D16: =COUNTA(Data!M2:M1001) | E16: =COUNTA(Data!M2:M1001) | F16: Use LOWER helper
A17: depth | B17: numeric | C17: Range | D17: =MIN(Data!N2:N1001)&" to "&MAX(Data!N2:N1001) | E17: =MIN(Data!N2:N1001)&" to "&MAX(Data!N2:N1001) | F17: Numeric
A18: latitude | B18: numeric | C18: Numeric check | D18: =ISNUMBER(Data!O2) | E18: =ISNUMBER(Data!O2) | F18: TRUE/FALSE sample check
A19: longitude | B19: numeric | C19: Numeric check | D19: =ISNUMBER(Data!P2) | E19: =ISNUMBER(Data!P2) | F19: TRUE/FALSE sample check
A20: location | B20: categorical | C20: Blank percentage | D20: =COUNTBLANK(Data!Q2:Q1001)/COUNTA(Data!A2:A1001) | E20: =COUNTBLANK(Data!Q2:Q1001)/COUNTA(Data!A2:A1001) | F20: Percent blank
A21: continent | B21: categorical | C21: Blank percentage | D21: =COUNTBLANK(Data!R2:R1001)/COUNTA(Data!A2:A1001) | E21: =COUNTBLANK(Data!R2:R1001)/COUNTA(Data!A2:A1001) | F21: Percent blank
A22: country | B22: categorical | C22: Blank percentage | D22: =COUNTBLANK(Data!S2:S1001)/COUNTA(Data!A2:A1001) | E22: =COUNTBLANK(Data!S2:S1001)/COUNTA(Data!A2:A1001) | F22: Percent blank
A25: Blank-Percentage Audit (1,000 rows) | E25: Alert Level Breakdown (blank included)
A26: Field | B26: Blank Count | C26: Blank Percentage | E26: Alert Level | F26: Count
A27: alert | B27: =COUNTBLANK(Data!F2:F1001) | C27: =B27/COUNTA(Data!A2:A1001) | E27: Blank | F27: =COUNTBLANK(Data!F2:F1001)
A28: continent | B28: =COUNTBLANK(Data!R2:R1001) | C28: =B28/COUNTA(Data!A2:A1001) | E28: green | F28: =COUNTIF(Data!F2:F1001,E28)
A29: country | B29: =COUNTBLANK(Data!S2:S1001) | C29: =B29/COUNTA(Data!A2:A1001) | E29: yellow | F29: =COUNTIF(Data!F2:F1001,E29)
A30: location | B30: =COUNTBLANK(Data!Q2:Q1001) | C30: =B30/COUNTA(Data!A2:A1001) | E30: orange | F30: =COUNTIF(Data!F2:F1001,E30)
E31: red | F31: =COUNTIF(Data!F2:F1001,E31)
A33: Date-Time Conversion Check
A34: Check | B34: Formula | C34: Result
A35: Raw date_time is number? | B35: =ISNUMBER(Data!C2) | C35: FALSE expected (raw is text)
A36: Converted date_time is number? | B36: =ISNUMBER(Data!T2) | C36: TRUE expected
A39: Title Pattern Audit | D39: Magnitude Type Casing Audit
A40: Pattern | B40: Count | D40: View | E40: Type | F40: Count
A41: Distance-prefix pattern | B41: =COUNTIF(Data!U2:U1001,A41) | D41: Raw | E41: Mi | F41: =COUNTIF(Data!M2:M1001,E41) | H41: Normalized | I41: mb | J41: =COUNTIF(Data!V2:V1001,I41)
A42: Named-region pattern | B42: =COUNTIF(Data!U2:U1001,A42) | D42: Raw | E42: mb | F42: =COUNTIF(Data!M2:M1001,E42) | H42: Normalized | I42: md | J42: =COUNTIF(Data!V2:V1001,I42)
D43: Raw | E43: md | F43: =COUNTIF(Data!M2:M1001,E43) | H43: Normalized | I43: mi | J43: =COUNTIF(Data!V2:V1001,I43)
D44: Raw | E44: ml | F44: =COUNTIF(Data!M2:M1001,E44) | H44: Normalized | I44: ml | J44: =COUNTIF(Data!V2:V1001,I44)
A45: Duplicate Event Audit | D45: Raw | E45: ms | F45: =COUNTIF(Data!M2:M1001,E45) | H45: Normalized | I45: ms | J45: =COUNTIF(Data!V2:V1001,I45)
A46: Duplicated rows (COUNTIFS flag) | B46: =COUNTIF(Data!W2:W1001,"Duplicate") | C46: Two duplicate groups were found; four rows belong to duplicated groups, meaning two are extra occurrences. | D46: Raw | E46: mw | F46: =COUNTIF(Data!M2:M1001,E46) | H46: Normalized | I46: mw | J46: =COUNTIF(Data!V2:V1001,I46)
...

Sheet Dashboard
A1: Earthquake Data Analytics Dashboard (1995–2023)
A2: Source: provided earthquake_1995-2023.csv | 1,000 significant earthquakes (magnitude 6.5+)
A4: Records | C4: Min Magnitude | E4: Max Magnitude | G4: Avg Magnitude
A5: =COUNTA(Data!A2:A1001) | C5: =MIN(Data!B2:B1001) | E5: =MAX(Data!B2:B1001) | G5: =AVERAGE(Data!B2:B1001)
I6: Go to Task 1
A7: Min Depth | C7: Max Depth | E7: Blank Alert | G7: Blank Continent | I7: Go to Task 2
A8: =MIN(Data!N2:N1001) | C8: =MAX(Data!N2:N1001) | E8: =COUNTBLANK(Data!F2:F1001)/COUNTA(Data!A2:A1001) | G8: =COUNTBLANK(Data!R2:R1001)/COUNTA(Data!A2:A1001) | I8: Go to PivotTables
I9: Go to Data Quality Summary
I10: Go to Data

Sheet Data Quality Summary
A1: Data Quality Summary — Issue and Lab 4 Fix
A3: Issue Found | B3: Evidence / Formula Result | C3: Fix to Apply in Lab 4 | D3: Priority
A4: Alert is heavily incomplete | B4: =COUNTBLANK(Data!F2:F1001)&" blanks ("&TEXT(COUNTBLANK(Data!F2:F1001)/COUNTA(Data!A2:A1001),"0.0%")&")" | C4: Keep missing as blank/NA or explicitly unassigned; do not invent alert values. | D4: High
A5: Continent is heavily incomplete | B5: =COUNTBLANK(Data!R2:R1001)&" blanks ("&TEXT(COUNTBLANK(Data!R2:R1001)/COUNTA(Data!A2:A1001),"0.0%")&")" | C5: Retain missing as NA; only impute from verified geographic mapping if required. | D5: High
A6: Country has missing values | B6: =COUNTBLANK(Data!S2:S1001)&" blanks ("&TEXT(COUNTBLANK(Data!S2:S1001)/COUNTA(Data!A2:A1001),"0.0%")&")" | C6: Retain missing as NA; avoid guessing country from incomplete metadata. | D6: Medium
A7: Location has a few missing values | B7: =COUNTBLANK(Data!Q2:Q1001)&" blanks ("&TEXT(COUNTBLANK(Data!Q2:Q1001)/COUNTA(Data!A2:A1001),"0.0%")&")" | C7: Keep missing as NA or derive only from trusted source fields. | D7: Medium
A8: date_time is stored as text | B8: =ISNUMBER(Data!C2) | C8: Convert with DATE/MID/TIME into DateTime_Converted and use that for sorting/charting. | D8: High
A9: Title has two formats | B9: =COUNTIF(Data!U2:U1001,"Distance-prefix pattern")&" distance-prefix; "&COUNTIF(Data!U2:U1001,"Named-region pattern")&" named-region" | C9: Keep a title-pattern flag; parse distance/city only when the pattern is present. | D9: Medium
A10: magType casing is inconsistent | B10: =COUNTIF(Data!M2:M1001,"Mi")&" raw Mi rows; normalized helper uses LOWER" | C10: Create normalized lowercase magType before grouping/comparison. | D10: Medium
A11: Near-duplicate events exist | B11: =COUNTIF(Data!W2:W1001,"Duplicate")&" rows flagged by title + timestamp" | C11: Use title + date_time duplicate check; review duplicate groups and retain the valid event record. | D11: High
A14: Assignment compliance notes
A15: All 1,000 records and 19 original columns are retained in the Data sheet.
A16: Helper columns are formula-driven: converted datetime, title pattern, normalized magType, duplicate flag, year, magnitude band, and alert audit.
A17: Task 1 contains live formulas for record count, ranges, average, magType counts, alert counts, and magnitude-band counts, plus charts.
A18: Task 2 contains the 19-column classification and formula-driven quality checks.
A19: PivotTable-style breakdowns are provided on the PivotTables sheet; Excel can refresh/filter them from the Data table.

Sheet Graphs
A1: EXTRA PART: EARTHQUAKE DATA VISUALIZATION
A3: Graph 1 - Earthquake Records per Year
A4: Year | B4: Number of Earthquake Records
D5: Decade | E5: Records
A37: Graph 3 - Magnitude Distribution
A38: Magnitude Range | B38: Frequency
A39: 6.5–7.0 | B39: 627
A40: 7.0–7.5 | B40: 229
A41: 7.5–8.0 | B41: 112
A42: 8.0–8.5 | B42: 27
A43: 8.5–9.0 | B43: 3
A44: 9.0–9.5 | B44: 2
A60: Graph 4 - Magnitude vs Depth
A61: Magnitude | B61: Depth
A62: 6.5 | B62: 192.955
A63: 6.5 | B63: 69.727
A64: 6.6 | B64: 171.371
A65: 7.2 | B65: 32.571
A66: 7.3 | B66: 21
A67: 6.6 | B67: 10
A68: 6.9 | B68: 229
A69: 7.2 | B69: 167.404
A70: 6.6 | B70: 10
A71: 7.1 | B71: 35.981
A72: 7.7 | B72: 18.027
A73: 7.6 | B73: 210.097
... A1061: 7.1 | B1061: 16

Sheet README
A1: LAB ASSIGNMENT 3 - EARTHQUAKE DATA
A3: Workbook Sheet Order
A4: 1. Data
A5: 2. Task 1 - Exploration
A6: 3. Task 2 - Quality Audit
A7: 4. Dashboard
A8: 5. Data Quality Summary
A9: 6. README
A11: Purpose
A12: This workbook contains the earthquake dataset, Task 1 exploration, Task 2 quality audit, dashboard, and data quality summary.
A14: Data Coverage
A15: The earthquake dataset contains records from 1995 to 2023.

Sheet PivotTables
A1: PivotTable Summaries
A2: These summaries are built from the Excel Data table and helper columns so they recalculate with the dataset. Use Excel Insert > PivotTable on EarthquakeData for a native PivotTable if your Excel version requires the PivotTable object.
A4: Event Count by Alert Level | D4: Event Count by magType (raw) | G4: Event Count by magType (normalized)
A5: Alert | B5: Count | D5: magType | E5: Count | G5: magType | H5: Count
A6: Blank | B6: =COUNTBLANK(Data!F2:F1001) | D6: Mi | E6: =COUNTIF(Data!M2:M1001,D6) | G6: mb | H6: =COUNTIF(Data!V2:V1001,G6)
A7: green | B7: =COUNTIF(Data!F2:F1001,A7) | D7: mb | E7: =COUNTIF(Data!M2:M1001,D7) | G7: md | H7: =COUNTIF(Data!V2:V1001,G7)
A8: yellow | B8: =COUNTIF(Data!F2:F1001,A8) | D8: md | E8: =COUNTIF(Data!M2:M1001,D8) | G8: mi | H8: =COUNTIF(Data!V2:V1001,G8)
A9: orange | B9: =COUNTIF(Data!F2:F1001,A9) | D9: ml | E9: =COUNTIF(Data!M2:M1001,D9) | G9: ml | H9: =COUNTIF(Data!V2:V1001,G9)
A10: red | B10: =COUNTIF(Data!F2:F1001,A10) | D10: ms | E10: =COUNTIF(Data!M2:M1001,D10) | G10: ms | H10: =COUNTIF(Data!V2:V1001,G10)
D11: mw | E11: =COUNTIF(Data!M2:M1001,D11) | G11: mw | H11: =COUNTIF(Data!V2:V1001,G11)
D12: mwb | E12: =COUNTIF(Data!M2:M1001,D12) | G12: mwb | H12: =COUNTIF(Data!V2:V1001,G12)
D13: mwc | E13: =COUNTIF(Data!M2:M1001,D13) | G13: mwc | H13: =COUNTIF(Data!V2:V1001,G13)
A14: Event Count by Title Pattern | D14: Duplicate Status | E14: =COUNTIF(Data!M2:M1001,D14) | G14: mww | H14: =COUNTIF(Data!V2:V1001,G14)
A15: Pattern | B15: Count | D15: Status | E15: Count
A16: Distance-prefix pattern | B16: =COUNTIF(Data!U2:U1001,A16) | D16: Unique | E16: =COUNTIF(Data!W2:W1001,D16)
A17: Named-region pattern | B17: =COUNTIF(Data!U2:U1001,A17) | D17: Duplicate | E17: =COUNTIF(Data!W2:W1001,D17)
A21: Events by Year
A22: Year | B22: Count
A23: 1995 | B23: =COUNTIF(Data!X2:X1001,A23)
A24: 1996 | B24: =COUNTIF(Data!X2:X1001,A24)
A25: 1997 | B25: =COUNTIF(Data!X2:X1001,A25)
A26: 1998 | B26: =COUNTIF(Data!X2:X1001,A26)
A27: 1999 | B27: =COUNTIF(Data!X2:X1001,A27)
A28: 2000 | B28: =COUNTIF(Data!X2:X1001,A28)
A29: 2001 | B29: =COUNTIF(Data!X2:X1001,A29)
A30: Filter | E30: Filter
A32: alert | B32: Count - title | E32: magType_Normalized | F32: Count - title
A33: green | B33: 353 | E33: mb | F33: 4
A34: orange | B34: 24 | E34: md | F34: 2
A35: red | B35: 13 | E35: mi | F35: 5
A36: yellow | B36: 59 | E36: ml | F36: 1
A37: (empty) | B37: 551 | E37: ms | F37: 3
A38: Total Result | B38: 1000 | E38: mw | F38: 51
A39: 2011 | B39: =COUNTIF(Data!X2:X1001,A39) | E39: mwb | F39: 100
A40: 2012 | B40: =COUNTIF(Data!X2:X1001,A40) | E40: mwc | F40: 332
A41: 2013 | B41: =COUNTIF(Data!X2:X1001,A41) | E41: mww | F41: 502
A42: 2014 | B42: =COUNTIF(Data!X2:X1001,A42) | E42: Total Result | F42: 1000
A43: 2015 | B43: =COUNTIF(Data!X2:X1001,A43)
A44: 2016 | B44: =COUNTIF(Data!X2:X1001,A44)
A45: 2017 | B45: =COUNTIF(Data!X2:X1001,A45)
...
